Workbook

Sheet komentzář a km
B37: Všední den neprázdninový
C38: Návrat | E38: Prinz
B39: Linka | C39: km | D39: km | E39: km | F39: km
B40: 561 | C40: 156 | D40: 174 | E40: ='561 '!Z19 -> 137.8 | F40: ='561 '!AC40 -> 190
B41: 562 | C41: 218 | D41: 209 | E41: ='562 '!J26 -> 65 | F41: ='562 '!J54 -> 65.2
B42: 563 | C42: 61 | D42: 48 | E42: ='563'!AI19 -> 128.7 | F42: ='563'!AI40 -> 120
B43: 564 | C43: 189 | D43: 179 | E43: 0 | F43: 0
B44: 565 | C44: 94 | D44: 123 | E44: ='565 '!W22 -> 79.8 | F44: ='565 '!W63 -> 83.6
B45: 566 | C45: 93 | D45: 108 | E45: ='566 '!V30 -> 161.8 | F45: ='566 '!AB59 -> 181.1
B46: 567 | C46: 92 | D46: 116 | E46: ='567 '!AP20 -> 116.2 | F46: ='567 '!AJ43 -> 156.8
B47: 568 | C47: 25 | D47: 50 | E47: ='568'!T21 -> 144 | F47: ='568'!U45 -> 153
B48: 569 | C48: 163 | D48: 173 | E48: ='569'!Z29 -> 224.4 | F48: ='569'!AC63 -> 260.3
B49: Km celkem | D49: =SUM(C40:D48) -> 2271 | F49: =SUM(E40:F48) -> 2267.7

Sheet 561 
A1: Linka číslo 745561 | D1: Městský hřbitov-Hlavní-Charvátská Nová Ves
B3: návrh k projednání
A4: Tč | D4: 1 | E4: =D4+2 -> 3 | F4: =E4+2 -> 5 | G4: =F4+2 -> 7 | H4: =G4+2 -> 9 | I4: =H4+2 -> 11 | J4: =I4+2 -> 13 | K4: =J4+2 -> 15 | L4: =K4+2 -> 17 | ... Y4: =X4+2 -> 43
A5: 1 | B5: Městský Hřbitov | C5: odj. | E5: 0.21875 | G5: 0.26041667 | I5: 0.30208333 | Q5: 0.59375 | S5: 0.63541667 | U5: 0.67708333 | W5: 0.71875 | Y5: 0.84375
A6: 2 | B6: Pohansko rozc. | E6: =E5+"0:02" -> 0.22013889 | G6: =G5+"0:02" -> 0.26180556 | I6: =I5+"0:02" -> 0.30347222 | Q6: =Q5+"0:02" -> 0.59513889 | S6: =S5+"0:02" -> 0.63680556 | U6: =U5+"0:02" -> 0.67847222 | W6: =W5+"0:02" -> 0.72013889 | Y6: =Y5+"0:02" -> 0.84513889
A7: 3 | B7: Gumotex | E7: =E6+"0:02" -> 0.22152778 | G7: =G6+"0:02" -> 0.26319444 | I7: =I6+"0:02" -> 0.30486111 | Q7: =Q6+"0:02" -> 0.59652778 | S7: =S6+"0:02" -> 0.63819444 | U7: =U6+"0:02" -> 0.67986111 | W7: =W6+"0:02" -> 0.72152778 | Y7: =Y6+"0:02" -> 0.84652778
A8: 4 | B8: Autobusové nádraží | C8: příj. | E8: =E7+"0:02" -> 0.22291667 | G8: =G7+"0:02" -> 0.26458333 | I8: =I7+"0:02" -> 0.30625 | Q8: =Q7+"0:02" -> 0.59791667 | S8: =S7+"0:02" -> 0.63958333 | U8: =U7+"0:02" -> 0.68125 | W8: =W7+"0:02" -> 0.72291667 | Y8: =Y7+"0:02" -> 0.84791667
A9: 4 | B9: Autobusové nádraží | C9: odj. | D9: 0.20972222 | E9: 0.22361111 | F9: 0.25138889 | G9: 0.26527778 | H9: 0.29305556 | I9: 0.30694444 | J9: 0.33472222 | K9: 0.37638889 | L9: 0.41805556 | M9: 0.45972222 | N9: 0.50138889 | O9: 0.54305556 | P9: 0.58472222 | Q9: 0.59861111 | R9: 0.62638889 | S9: 0.64027778 | T9: 0.66805556 | U9: 0.68194444 | V9: 0.70972222 | W9: 0.72361111 | X9: 0.75138889 | Y9: 0.84861111
A10: 5 | B10: Jana Palacha | D10: =D9+"0:03" -> 0.21180556 | E10: =E9+"0:03" -> 0.22569444 | F10: =F9+"0:03" -> 0.25347222 | G10: =G9+"0:03" -> 0.26736111 | H10: =H9+"0:03" -> 0.29513889 | I10: =I9+"0:03" -> 0.30902778 | J10: =J9+"0:03" -> 0.33680556 | K10: =K9+"0:03" -> 0.37847222 | ... Y10: =Y9+"0:03" -> 0.85069444
A11: 6 | B11: nám.TGM kostel | D11: =D10+"0:03" -> 0.21388889 | E11: =E10+"0:03" -> 0.22777778 | F11: =F10+"0:03" -> 0.25555556 | G11: =G10+"0:03" -> 0.26944444 | H11: =H10+"0:03" -> 0.29722222 | I11: =I10+"0:03" -> 0.31111111 | J11: =J10+"0:03" -> 0.33888889 | K11: =K10+"0:03" -> 0.38055556 | ... Y11: =Y10+"0:03" -> 0.85277778
A12: 7 | B12: Poštorná,Lesní | D12: =D11+"0:02" -> 0.21527778 | E12: =E11+"0:02" -> 0.22916667 | F12: =F11+"0:02" -> 0.25694444 | G12: =G11+"0:02" -> 0.27083333 | H12: =H11+"0:02" -> 0.29861111 | I12: =I11+"0:02" -> 0.3125 | J12: =J11+"0:02" -> 0.34027778 | K12: =K11+"0:02" -> 0.38194444 | ... Y12: =Y11+"0:02" -> 0.85416667
A13: 8 | B13: Poštorná,kostel | D13: =D12+"0:01" -> 0.21597222 | E13: =E12+"0:01" -> 0.22986111 | F13: =F12+"0:01" -> 0.25763889 | G13: =G12+"0:01" -> 0.27152778 | H13: =H12+"0:01" -> 0.29930556 | I13: =I12+"0:01" -> 0.31319444 | J13: =J12+"0:01" -> 0.34097222 | K13: =K12+"0:01" -> 0.38263889 | ... Y13: =Y12+"0:01" -> 0.85486111
A14: 9 | B14: Poštorná,Hlavní | D14: =D13+"0:01" -> 0.21666667 | E14: =E13+"0:01" -> 0.23055556 | F14: =F13+"0:01" -> 0.25833333 | G14: =G13+"0:01" -> 0.27222222 | H14: =H13+"0:01" -> 0.3 | I14: =I13+"0:01" -> 0.31388889 | J14: =J13+"0:01" -> 0.34166667 | K14: =K13+"0:01" -> 0.38333333 | ... Y14: =Y13+"0:01" -> 0.85555556
A15: 10 | B15: Poštorná,Hlavní na konci | D15: =D14+"0:01" -> 0.21736111 | E15: =E14+"0:01" -> 0.23125 | F15: =F14+"0:01" -> 0.25902778 | G15: =G14+"0:01" -> 0.27291667 | H15: =H14+"0:01" -> 0.30069444 | I15: =I14+"0:01" -> 0.31458333 | J15: =J14+"0:01" -> 0.34236111 | K15: =K14+"0:01" -> 0.38402778 | ... Y15: =Y14+"0:01" -> 0.85625
A16: 11 | B16: Charvátská N.Ves,Palackého | D16: =D15+"0:01" -> 0.21805556 | E16: =E15+"0:01" -> 0.23194444 | F16: =F15+"0:01" -> 0.25972222 | G16: =G15+"0:01" -> 0.27361111 | H16: =H15+"0:01" -> 0.30138889 | I16: =I15+"0:01" -> 0.31527778 | J16: =J15+"0:01" -> 0.34305556 | K16: =K15+"0:01" -> 0.38472222 | ... Y16: =Y15+"0:01" -> 0.85694444
A17: 12 | B17: Charvátská N.Ves,Lednická | D17: =D16+"0:01" -> 0.21875 | E17: =E16+"0:01" -> 0.23263889 | F17: =F16+"0:01" -> 0.26041667 | G17: =G16+"0:01" -> 0.27430556 | H17: =H16+"0:01" -> 0.30208333 | I17: =I16+"0:01" -> 0.31597222 | J17: =J16+"0:01" -> 0.34375 | K17: =K16+"0:01" -> 0.38541667 | ... Y17: =Y16+"0:01" -> 0.85763889
A18: 13 | B18: Charvátská N.Ves,Obránců míru | C18: příj. | D18: =D17+"0:01" -> 0.21944444 | E18: =E17+"0:01" -> 0.23333333 | F18: =F17+"0:01" -> 0.26111111 | G18: =G17+"0:01" -> 0.275 | H18: =H17+"0:01" -> 0.30277778 | I18: =I17+"0:01" -> 0.31666667 | J18: =J17+"0:01" -> 0.34444444 | K18: =K17+"0:01" -> 0.38611111 | ... Y18: =Y17+"0:01" -> 0.85833333
B19: km | D19: 5.5 | E19: 7.6 | F19: 5.5 | G19: 7.6 | H19: 5.5 | I19: 7.6 | J19: 5.5 | K19: 5.5 | L19: 5.5 | M19: 5.5 | N19: 5.5 | O19: 5.5 | P19: 5.5 | Q19: 7.6 | R19: 5.5 | S19: 7.6 | T19: 5.5 | U19: 7.6 | V19: 5.5 | W19: 7.6 | X19: 5.5 | Y19: 7.6 | Z19: =SUM(D19:Y19) -> 137.8
A22: Linka číslo 745561 | D22: Charvatská Nová Ves - Hlavní - Městský Hřbitov
B24: návrh k projednání
A25: Tč | D25: 2 | E25: 4 | F25: 6 | G25: 8 | H25: 10 | I25: 12 | J25: 14 | K25: 16 | L25: 18 | M25: 20 | N25: 22 | O25: 24 | P25: 26 | Q25: 28 | R25: 30 | S25: 32 | T25: 34 | U25: 36 | V25: 38 | W25: 40 | X25: 42 | Y25: 44 | Z25: 46 | AA25: 48 | AB25: 50
A26: 13 | B26: Charvátská N.Ves,Obránců míru | C26: odj. | D26: 0.21180556 | E26: 0.22222222 | F26: 0.25347222 | G26: 0.26388889 | H26: 0.29513889 | I26: 0.30555556 | J26: 0.34722222 | K26: 0.38888889 | L26: 0.43055556 | M26: 0.47222222 | N26: 0.51388889 | O26: 0.55555556 | P26: 0.58680556 | Q26: 0.59722222 | R26: 0.62847222 | S26: 0.63888889 | T26: 0.67013889 | U26: 0.68055556 | V26: 0.71180556 | W26: 0.72222222 | X26: 0.75347222 | Y26: 0.76388889 | Z26: 0.81041667 | AA26: 0.85208333 | AB26: 0.89375
A27: 12 | B27: Charvátská N.Ves,Lednická | D27: =D26+"0:01" -> 0.2125 | E27: =E26+"0:01" -> 0.22291667 | F27: =F26+"0:01" -> 0.25416667 | G27: =G26+"0:01" -> 0.26458333 | H27: =H26+"0:01" -> 0.29583333 | I27: =I26+"0:01" -> 0.30625 | J27: =J26+"0:01" -> 0.34791667 | K27: =K26+"0:01" -> 0.38958333 | ... AB27: =AB26+"0:01" -> 0.89444444
A28: 11 | B28: Charvátská N.Ves,Palackého | D28: =D27+"0:01" -> 0.21319444 | E28: =E27+"0:01" -> 0.22361111 | F28: =F27+"0:01" -> 0.25486111 | G28: =G27+"0:01" -> 0.26527778 | H28: =H27+"0:01" -> 0.29652778 | I28: =I27+"0:01" -> 0.30694444 | J28: =J27+"0:01" -> 0.34861111 | K28: =K27+"0:01" -> 0.39027778 | ... AB28: =AB27+"0:01" -> 0.89513889
A29: 10 | B29: Poštorná,Hlavní na konci | D29: =D28+"0:01" -> 0.21388889 | E29: =E28+"0:01" -> 0.22430556 | F29: =F28+"0:01" -> 0.25555556 | G29: =G28+"0:01" -> 0.26597222 | H29: =H28+"0:01" -> 0.29722222 | I29: =I28+"0:01" -> 0.30763889 | J29: =J28+"0:01" -> 0.34930556 | K29: =K28+"0:01" -> 0.39097222 | ... AB29: =AB28+"0:01" -> 0.89583333
A30: 9 | B30: Poštorná,Hlavní | D30: =D29+"0:01" -> 0.21458333 | E30: =E29+"0:01" -> 0.225 | F30: =F29+"0:01" -> 0.25625 | G30: =G29+"0:01" -> 0.26666667 | H30: =H29+"0:01" -> 0.29791667 | I30: =I29+"0:01" -> 0.30833333 | J30: =J29+"0:01" -> 0.35 | K30: =K29+"0:01" -> 0.39166667 | ... AB30: =AB29+"0:01" -> 0.89652778
A31: 8 | B31: Poštorná,kostel | D31: =D30+"0:01" -> 0.21527778 | E31: =E30+"0:01" -> 0.22569444 | F31: =F30+"0:01" -> 0.25694444 | G31: =G30+"0:01" -> 0.26736111 | H31: =H30+"0:01" -> 0.29861111 | I31: =I30+"0:01" -> 0.30902778 | J31: =J30+"0:01" -> 0.35069444 | K31: =K30+"0:01" -> 0.39236111 | ... AB31: =AB30+"0:01" -> 0.89722222
A32: 7 | B32: Poštorná,Lesní | D32: =D31+"0:01" -> 0.21597222 | E32: =E31+"0:01" -> 0.22638889 | F32: =F31+"0:01" -> 0.25763889 | G32: =G31+"0:01" -> 0.26805556 | H32: =H31+"0:01" -> 0.29930556 | I32: =I31+"0:01" -> 0.30972222 | J32: =J31+"0:01" -> 0.35138889 | K32: =K31+"0:01" -> 0.39305556 | ... AB32: =AB31+"0:01" -> 0.89791667
A33: 6 | B33: nám.TGM kostel | D33: =D32+"0:02" -> 0.21736111 | E33: =E32+"0:02" -> 0.22777778 | F33: =F32+"0:02" -> 0.25902778 | G33: =G32+"0:02" -> 0.26944444 | H33: =H32+"0:02" -> 0.30069444 | I33: =I32+"0:02" -> 0.31111111 | J33: =J32+"0:02" -> 0.35277778 | K33: =K32+"0:02" -> 0.39444444 | ... AB33: =AB32+"0:02" -> 0.89930556
A34: 5 | B34: Jana Palacha | D34: =D33+"0:02" -> 0.21875 | E34: =E33+"0:02" -> 0.22916667 | F34: =F33+"0:02" -> 0.26041667 | G34: =G33+"0:02" -> 0.27083333 | H34: =H33+"0:02" -> 0.30208333 | I34: =I33+"0:02" -> 0.3125 | J34: =J33+"0:02" -> 0.35416667 | K34: =K33+"0:02" -> 0.39583333 | ... AB34: =AB33+"0:02" -> 0.90069444
A35: 4 | B35: Autobusové nádraží | C35: příj. | D35: =D34+"0:03" -> 0.22083333 | E35: =E34+"0:03" -> 0.23125 | F35: =F34+"0:03" -> 0.2625 | G35: =G34+"0:03" -> 0.27291667 | H35: =H34+"0:03" -> 0.30416667 | I35: =I34+"0:03" -> 0.31458333 | J35: =J34+"0:03" -> 0.35625 | K35: =K34+"0:03" -> 0.39791667 | ... Y35: =Y34+"0:03" -> 0.77291667 | Z35: =Z34+"0:02" -> 0.81875 | AA35: =AA34+"0:02" -> 0.86041667 | AB35: =AB34+"0:02" -> 0.90208333
A36: 4 | B36: Autobusové nádraží | C36: odj. | D36: =D35+"0:04" -> 0.22361111 | E36: 0.23402778 | F36: =F35+"0:04" -> 0.26527778 | G36: 0.27569444 | H36: =H35+"0:04" -> 0.30694444 | I36: 0.31736111 | J36: 0.35902778 | K36: 0.40069444 | L36: 0.44236111 | M36: 0.48402778 | N36: 0.52569444 | O36: 0.56736111 | P36: =P35+"0:04" -> 0.59861111 | Q36: 0.60902778 | R36: =R35+"0:04" -> 0.64027778 | S36: 0.65069444 | T36: =T35+"0:04" -> 0.68194444 | U36: 0.69236111 | V36: =V35+"0:04" -> 0.72361111 | W36: 0.73402778 | X36: =X35+"0:04" -> 0.76527778 | Y36: 0.77569444 | Z36: 0.81944444 | AA36: 0.86111111 | AB36: 0.90277778
A37: 3 | B37: BORS | D37: =D36+"0:02" -> 0.225 | E37: =E36+"0:02" -> 0.23541667 | F37: =F36+"0:02" -> 0.26666667 | G37: =G36+"0:02" -> 0.27708333 | H37: =H36+"0:02" -> 0.30833333 | I37: =I36+"0:02" -> 0.31875 | J37: =J36+"0:02" -> 0.36041667 | K37: =K36+"0:02" -> 0.40208333 | ... AB37: =AB36+"0:02" -> 0.90416667
A38: 2 | B38: Pohansko rozc. | D38: =D37+"0:01" -> 0.22569444 | E38: =E37+"0:01" -> 0.23611111 | F38: =F37+"0:01" -> 0.26736111 | G38: =G37+"0:01" -> 0.27777778 | H38: =H37+"0:01" -> 0.30902778 | I38: =I37+"0:01" -> 0.31944444 | J38: =J37+"0:01" -> 0.36111111 | K38: =K37+"0:01" -> 0.40277778 | ... AB38: =AB37+"0:01" -> 0.90486111
A39: 1 | B39: Městský Hřbitov | C39: příj. | D39: =D38+"0:02" -> 0.22708333 | E39: =E38+"0:02" -> 0.2375 | F39: =F38+"0:02" -> 0.26875 | G39: =G38+"0:02" -> 0.27916667 | H39: =H38+"0:02" -> 0.31041667 | I39: =I38+"0:02" -> 0.32083333 | J39: =J38+"0:02" -> 0.3625 | K39: =K38+"0:02" -> 0.40416667 | ... AB39: =AB38+"0:02" -> 0.90625
B40: km | D40: 7.6 | E40: 7.6 | F40: 7.6 | G40: 7.6 | H40: 7.6 | I40: 7.6 | J40: 7.6 | K40: 7.6 | L40: 7.6 | M40: 7.6 | N40: 7.6 | O40: 7.6 | P40: 7.6 | Q40: 7.6 | R40: 7.6 | S40: 7.6 | T40: 7.6 | U40: 7.6 | V40: 7.6 | W40: 7.6 | X40: 7.6 | Y40: 7.6 | Z40: 7.6 | AA40: 7.6 | AB40: 7.6 | AC40: =SUM(D40:AB40) -> 190

Sheet 562 
A1: Linka číslo 745562 | E1: Městský hřbitov-Valtická Točna-Charvátská Nová Ves
B2: návrh k projednání
A3: Tč | D3: 1 | E3: 3 | F3: 5 | G3: 7 | H3: 9 | I3: 11
A4: 1 | B4: Městský hřbitov | C4: odj. | F4: 0.87083333 | G4: 0.89513889 | H4: 0.92569444
A5: 2 | B5: Lanžhotská | F5: ~ | G5: ~ | H5: ~
A6: 3 | B6: Pohansko rozc. | F6: =F4+"0:02" -> 0.87222222 | G6: =G4+"0:02" -> 0.89652778 | H6: =H4+"0:02" -> 0.92708333
A7: 4 | B7: Gumotex | F7: =F6+"0:01" -> 0.87291667 | G7: =G6+"0:01" -> 0.89722222 | H7: =H6+"0:01" -> 0.92777778
A8: 5 | B8: BORS | F8: ~ | G8: ~ | H8: ~
A9: 6 | B9: Autobusové nádraží | D9: 0.79166667 | E9: 0.83333333 | F9: 21:00 | G9: =G7+"0:03" -> 0.89930556 | H9: 0.92916667 | I9: 0.97291667
A10: 7 | B10: Jana Palacha | D10: =D9+"0:02" -> 0.79305556 | E10: =E9+"0:02" -> 0.83472222 | F10: =F9+"0:02" -> 0.87638889 | G10: =G9+"0:02" -> 0.90069444 | H10: =H9+"0:02" -> 0.93055556 | I10: =I9+"0:02" -> 0.97430556
A11: 8 | B11: Dům kultury | D11: =D10+"0:02" -> 0.79444444 | E11: =E10+"0:02" -> 0.83611111 | F11: =F10+"0:02" -> 0.87777778 | G11: =G10+"0:02" -> 0.90208333 | H11: =H10+"0:02" -> 0.93194444
A12: 9 | B12: poliklinika | D12: =D11+"0:01" -> 0.79513889 | E12: =E11+"0:01" -> 0.83680556 | F12: =F11+"0:01" -> 0.87847222 | G12: =G11+"0:01" -> 0.90277778 | H12: =H11+"0:01" -> 0.93263889
A13: 10 | B13: Dům kultury | D13: ~ | E13: ~ | F13: ~ | G13: ~ | H13: ~ | I13: ~
A14: 11 | B14: nám.TGM kostel | D14: =D12+"0:03" -> 0.79722222 | E14: =E12+"0:03" -> 0.83888889 | F14: =F12+"0:03" -> 0.88055556 | G14: =G12+"0:03" -> 0.90486111 | H14: =H12+"0:03" -> 0.93472222 | I14: 0.97638889
A15: 12 | B15: Poštorná,Lesní | D15: =D14+"0:03" -> 0.79930556 | E15: =E14+"0:03" -> 0.84097222 | F15: =F14+"0:03" -> 0.88263889 | G15: =G14+"0:02" -> 0.90625 | H15: =H14+"0:02" -> 0.93611111 | I15: =I14+"0:02" -> 0.97777778
A16: 13 | B16: Poštorná,kostel | D16: =D15+"0:01" -> 0.8 | E16: =E15+"0:01" -> 0.84166667 | F16: =F15+"0:01" -> 0.88333333 | G16: =G15+"0:01" -> 0.90694444 | H16: =H15+"0:01" -> 0.93680556 | I16: =I15+"0:01" -> 0.97847222
A17: 14 | B17: Poštorná,Nádražní | D17: =D16+"0:02" -> 0.80138889 | E17: =E16+"0:02" -> 0.84305556 | F17: =F16+"0:02" -> 0.88472222 | G17: =G16+"0:01" -> 0.90763889 | H17: =H16+"0:01" -> 0.9375 | I17: =I16+"0:01" -> 0.97916667
A18: 15 | B18: Poštorná,PKZ | D18: =D17+"0:01" -> 0.80208333 | E18: =E17+"0:01" -> 0.84375 | F18: =F17+"0:01" -> 0.88541667 | G18: =G17+"0:01" -> 0.90833333 | H18: =H17+"0:01" -> 0.93819444 | I18: =I17+"0:01" -> 0.97986111
A19: 16 | B19: Poštorná,Tovární čtvrť | D19: =D18+"0:02" -> 0.80347222 | E19: =E18+"0:02" -> 0.84513889 | F19: =F18+"0:02" -> 0.88680556 | G19: =G18+"0:02" -> 0.90972222 | H19: =H18+"0:02" -> 0.93958333 | I19: =I18+"0:02" -> 0.98125
A20: 17 | B20: Poštorná,Valtická točna | D20: =D19+"0:02" -> 0.80486111 | E20: =E19+"0:02" -> 0.84652778 | F20: =F19+"0:02" -> 0.88819444 | G20: =G19+"0:01" -> 0.91041667 | H20: =H19+"0:01" -> 0.94027778 | I20: =I19+"0:01" -> 0.98194444
A21: 18 | B21: Poštorná,Valtická | D21: =D20+"0:02" -> 0.80625 | E21: =E20+"0:02" -> 0.84791667 | F21: =F20+"0:02" -> 0.88958333 | G21: =G20+"0:02" -> 0.91180556 | H21: =H20+"0:02" -> 0.94166667 | I21: =I20+"0:02" -> 0.98333333
A22: 19 | B22: Poštorná,Hlavní na konci | D22: =D21+"0:01" -> 0.80694444 | E22: =E21+"0:01" -> 0.84861111 | F22: =F21+"0:01" -> 0.89027778 | G22: =G21+"0:01" -> 0.9125 | H22: =H21+"0:01" -> 0.94236111 | I22: =I21+"0:01" -> 0.98402778
A23: 20 | B23: Charvátská N.Ves,Palackého | D23: =D22+"0:02" -> 0.80833333 | E23: =E22+"0:02" -> 0.85 | F23: =F22+"0:02" -> 0.89166667 | G23: =G22+"0:01" -> 0.91319444 | H23: =H22+"0:01" -> 0.94305556 | I23: =I22+"0:01" -> 0.98472222
A24: 21 | B24: Charvátská N.Ves,Lednická | D24: =D23+"0:01" -> 0.80902778 | E24: =E23+"0:01" -> 0.85069444 | F24: =F23+"0:01" -> 0.89236111 | G24: =G23+"0:01" -> 0.91388889 | H24: =H23+"0:01" -> 0.94375 | I24: =I23+"0:01" -> 0.98541667
A25: 22 | B25: Charvátská N.Ves,Obránců míru | C25: příj. | D25: =D24+"0:01" -> 0.80972222 | E25: =E24+"0:01" -> 0.85138889 | F25: =F24+"0:01" -> 0.89305556 | G25: =G24+"0:01" -> 0.91458333 | H25: =H24+"0:01" -> 0.94444444 | I25: =I24+"0:01" -> 0.98611111
B26: km | D26: 10.1 | E26: 10.1 | F26: 12.2 | G26: 12.2 | H26: 12.2 | I26: 8.2 | J26: =SUM(D26:I26) -> 65
A29: Linka číslo 745562 | E29: Charvatská Nová Ves - Valtická Točna - Městský Hřbitov
B30: návrh k projednání | C30: opačný směr
A31: Tč | D31: 2 | E31: 4 | F31: 6 | G31: 8 | H31: 10 | I31: 12
A32: 22 | B32: Charvátská N.Ves,Obránců míru | C32: odj. | D32: 0.17013889 | E32: 0.79513889 | F32: 0.83680556 | G32: 0.87847222 | H32: 0.91458333 | I32: 0.94444444
A33: 21 | B33: Charvátská N.Ves,Lednická | D33: =D32+"0:01" -> 0.17083333 | E33: =E32+"0:01" -> 0.79583333 | F33: =F32+"0:01" -> 0.8375 | G33: =G32+"0:01" -> 0.87916667 | H33: =H32+"0:01" -> 0.91527778 | I33: =I32+"0:01" -> 0.94513889
A34: 20 | B34: Charvátská N.Ves,Palackého | D34: =D33+"0:01" -> 0.17152778 | E34: =E33+"0:01" -> 0.79652778 | F34: =F33+"0:01" -> 0.83819444 | G34: =G33+"0:01" -> 0.87986111 | H34: =H33+"0:01" -> 0.91597222 | I34: =I33+"0:01" -> 0.94583333
A35: 19 | B35: Poštorná,Hlavní na konci | D35: =D34+"0:01" -> 0.17222222 | E35: =E34+"0:02" -> 0.79791667 | F35: =F34+"0:02" -> 0.83958333 | G35: =G34+"0:02" -> 0.88125 | H35: =H34+"0:02" -> 0.91736111 | I35: =I34+"0:02" -> 0.94722222
A36: 18 | B36: Poštorná,Valtická | D36: =D35+"0:02" -> 0.17361111 | E36: =E35+"0:02" -> 0.79930556 | F36: =F35+"0:02" -> 0.84097222 | G36: =G35+"0:02" -> 0.88263889 | H36: =H35+"0:02" -> 0.91875 | I36: =I35+"0:02" -> 0.94861111
A37: 17 | B37: Poštorná,Valtická točna | D37: =D36+"0:01" -> 0.17430556 | E37: =E36+"0:03" -> 0.80138889 | F37: =F36+"0:03" -> 0.84305556 | G37: =G36+"0:03" -> 0.88472222 | H37: =H36+"0:03" -> 0.92083333 | I37: =I36+"0:03" -> 0.95069444
A38: 16 | B38: Poštorná,Tovární čtvrť | D38: =D37+"0:01" -> 0.175 | E38: =E37+"0:02" -> 0.80277778 | F38: =F37+"0:02" -> 0.84444444 | G38: =G37+"0:02" -> 0.88611111 | H38: =H37+"0:02" -> 0.92222222 | I38: =I37+"0:02" -> 0.95208333
A39: 15 | B39: Poštorná,PKZ | D39: =D38+"0:01" -> 0.17569444 | E39: =E38+"0:01" -> 0.80347222 | F39: =F38+"0:01" -> 0.84513889 | G39: =G38+"0:01" -> 0.88680556 | H39: =H38+"0:01" -> 0.92291667 | I39: =I38+"0:01" -> 0.95277778
A40: 14 | B40: Poštorná,Nádražní | D40: =D39+"0:01" -> 0.17638889 | E40: =E39+"0:02" -> 0.80486111 | F40: =F39+"0:02" -> 0.84652778 | G40: =G39+"0:02" -> 0.88819444 | H40: =H39+"0:02" -> 0.92430556 | I40: =I39+"0:02" -> 0.95416667
A41: 13 | B41: Poštorná,kostel | D41: =D40+"0:02" -> 0.17777778 | E41: =E40+"0:02" -> 0.80625 | F41: =F40+"0:02" -> 0.84791667 | G41: =G40+"0:02" -> 0.88958333 | H41: =H40+"0:02" -> 0.92569444 | I41: =I40+"0:02" -> 0.95555556
A42: 12 | B42: Poštorná,Lesní | D42: =D41+"0:01" -> 0.17847222 | E42: =E41+"0:02" -> 0.80763889 | F42: =F41+"0:02" -> 0.84930556 | G42: =G41+"0:02" -> 0.89097222 | H42: =H41+"0:02" -> 0.92708333 | I42: =I41+"0:02" -> 0.95694444
...

Sheet 563
A1: Linka číslo 745563 | C1: Autobusové nádraží-Slovácká - Cukrovar - Poliklinika - Poštorná,FOSFA
B3: návrh k projednání
A4: Tč | D4: 1 | E4: =D4+2 -> 3 | F4: =E4+2 -> 5 | G4: =F4+2 -> 7 | H4: =G4+2 -> 9 | I4: =H4+2 -> 11 | J4: =I4+2 -> 13 | K4: =J4+2 -> 15 | L4: =K4+2 -> 17 | ... R4: =Q4+2 -> 29 | T4: 33 | U4: =T4+2 -> 35 | V4: =U4+2 -> 37 | W4: =V4+2 -> 39 | X4: =W4+2 -> 41 | Y4: =X4+2 -> 43 | Z4: =Y4+2 -> 45 | AA4: =Z4+2 -> 47 | AB4: =AA4+2 -> 49 | ... AE4: =AD4+2 -> 55 | AG4: 59 | AH4: =AG4+2 -> 61
A5: 1 | B5: Autobusové nádraží | C5: odj. | E5: 5:08 | H5: 0.25555556 | K5: 0.29722222 | M5: 0.33888889 | N5: 0.38055556 | O5: 0.42222222 | P5: 0.46388889 | Q5: 0.50555556 | R5: 0.54722222 | U5: 0.58888889 | X5: 0.63055556 | AA5: 0.67222222 | AD5: 0.71388889 | AG5: 0.75555556 | AH5: 0.83888889
A6: 2 | B6: Jana Palacha | E6: =E5+"0:03" -> 0.21597222 | H6: =H5+"0:03" -> 0.25763889 | K6: =K5+"0:03" -> 0.29930556 | M6: =M5+"0:03" -> 0.34097222 | N6: =N5+"0:03" -> 0.38263889 | O6: =O5+"0:03" -> 0.42430556 | P6: =P5+"0:03" -> 0.46597222 | Q6: =Q5+"0:03" -> 0.50763889 | R6: =R5+"0:03" -> 0.54930556 | U6: =U5+"0:03" -> 0.59097222 | X6: =X5+"0:03" -> 0.63263889 | AA6: =AA5+"0:03" -> 0.67430556 | AD6: =AD5+"0:03" -> 0.71597222 | AG6: =AG5+"0:03" -> 0.75763889 | AH6: =AH5+"0:03" -> 0.84097222
A7: 3 | B7: Slovácká | E7: =E6+"0:02" -> 0.21736111 | H7: =H6+"0:02" -> 0.25902778 | K7: =K6+"0:02" -> 0.30069444 | M7: =M6+"0:02" -> 0.34236111 | N7: =N6+"0:02" -> 0.38402778 | O7: =O6+"0:02" -> 0.42569444 | P7: =P6+"0:02" -> 0.46736111 | Q7: =Q6+"0:02" -> 0.50902778 | R7: =R6+"0:02" -> 0.55069444 | U7: =U6+"0:02" -> 0.59236111 | X7: =X6+"0:02" -> 0.63402778 | AA7: =AA6+"0:02" -> 0.67569444 | AD7: =AD6+"0:02" -> 0.71736111 | AG7: =AG6+"0:02" -> 0.75902778 | AH7: =AH6+"0:02" -> 0.84236111
A8: 4 | B8: Sovadinova | E8: =E7+"0:02" -> 0.21875 | H8: =H7+"0:02" -> 0.26041667 | K8: =K7+"0:02" -> 0.30208333 | M8: =M7+"0:02" -> 0.34375 | N8: =N7+"0:02" -> 0.38541667 | O8: =O7+"0:02" -> 0.42708333 | P8: =P7+"0:02" -> 0.46875 | Q8: =Q7+"0:02" -> 0.51041667 | R8: =R7+"0:02" -> 0.55208333 | U8: =U7+"0:02" -> 0.59375 | X8: =X7+"0:02" -> 0.63541667 | AA8: =AA7+"0:02" -> 0.67708333 | AD8: =AD7+"0:02" -> 0.71875 | AG8: =AG7+"0:02" -> 0.76041667 | AH8: =AH7+"0:02" -> 0.84375
A9: 5 | B9: Cukrovar | E9: =E8+"0:02" -> 0.22013889 | H9: =H8+"0:02" -> 0.26180556 | K9: =K8+"0:02" -> 0.30347222 | M9: =M8+"0:02" -> 0.34513889 | N9: =N8+"0:02" -> 0.38680556 | O9: =O8+"0:02" -> 0.42847222 | P9: =P8+"0:02" -> 0.47013889 | Q9: =Q8+"0:02" -> 0.51180556 | R9: =R8+"0:02" -> 0.55347222 | U9: =U8+"0:02" -> 0.59513889 | X9: =X8+"0:02" -> 0.63680556 | AA9: =AA8+"0:02" -> 0.67847222 | AD9: =AD8+"0:02" -> 0.72013889 | AG9: =AG8+"0:02" -> 0.76180556 | AH9: =AH8+"0:02" -> 0.84513889
A10: 6 | B10: Nám. TGM, mě. Ú. | E10: =E9+"0:02" -> 0.22152778 | H10: =H9+"0:02" -> 0.26319444 | K10: =K9+"0:02" -> 0.30486111 | M10: =M9+"0:02" -> 0.34652778 | N10: =N9+"0:02" -> 0.38819444 | O10: =O9+"0:02" -> 0.42986111 | P10: =P9+"0:02" -> 0.47152778 | Q10: =Q9+"0:02" -> 0.51319444 | R10: =R9+"0:02" -> 0.55486111 | U10: =U9+"0:02" -> 0.59652778 | X10: =X9+"0:02" -> 0.63819444 | AA10: =AA9+"0:02" -> 0.67986111 | AD10: =AD9+"0:02" -> 0.72152778 | AG10: =AG9+"0:02" -> 0.76319444 | AH10: =AH9+"0:02" -> 0.84652778
A11: 7 | B11: Dům kultury | E11: =E10+"0:01" -> 0.22222222 | H11: =H10+"0:01" -> 0.26388889 | K11: =K10+"0:01" -> 0.30555556 | M11: =M10+"0:01" -> 0.34722222 | N11: =N10+"0:01" -> 0.38888889 | O11: =O10+"0:01" -> 0.43055556 | P11: =P10+"0:01" -> 0.47222222 | Q11: =Q10+"0:01" -> 0.51388889 | R11: =R10+"0:01" -> 0.55555556 | U11: =U10+"0:01" -> 0.59722222 | X11: =X10+"0:01" -> 0.63888889 | AA11: =AA10+"0:01" -> 0.68055556 | AD11: =AD10+"0:01" -> 0.72222222 | AG11: =AG10+"0:01" -> 0.76388889 | AH11: =AH10+"0:01" -> 0.84722222
A12: 8 | B12: Poliklinika | E12: =E11+"0:01" -> 0.22291667 | H12: =H11+"0:01" -> 0.26458333 | K12: =K11+"0:01" -> 0.30625 | M12: =M11+"0:01" -> 0.34791667 | N12: =N11+"0:01" -> 0.38958333 | O12: =O11+"0:01" -> 0.43125 | P12: =P11+"0:01" -> 0.47291667 | Q12: =Q11+"0:01" -> 0.51458333 | R12: =R11+"0:01" -> 0.55625 | U12: =U11+"0:01" -> 0.59791667 | X12: =X11+"0:01" -> 0.63958333 | AA12: =AA11+"0:01" -> 0.68125 | AD12: =AD11+"0:01" -> 0.72291667 | AG12: =AG11+"0:01" -> 0.76458333 | AH12: =AH11+"0:01" -> 0.84791667
A13: 9 | B13: Nemocnice | E13: =E12+"0:01" -> 0.22361111 | H13: =H12+"0:01" -> 0.26527778 | K13: =K12+"0:01" -> 0.30694444 | M13: =M12+"0:01" -> 0.34861111 | N13: =N12+"0:01" -> 0.39027778 | O13: =O12+"0:01" -> 0.43194444 | P13: =P12+"0:01" -> 0.47361111 | Q13: =Q12+"0:01" -> 0.51527778 | R13: =R12+"0:01" -> 0.55694444 | U13: =U12+"0:01" -> 0.59861111 | X13: =X12+"0:01" -> 0.64027778 | AA13: =AA12+"0:01" -> 0.68194444 | AD13: =AD12+"0:01" -> 0.72361111 | AG13: =AG12+"0:01" -> 0.76527778 | AH13: =AH12+"0:01" -> 0.84861111
A14: 10 | B14: Poštorná,Lesní | E14: =E13+"0:01" -> 0.22430556 | H14: =H13+"0:01" -> 0.26597222 | K14: =K13+"0:01" -> 0.30763889 | M14: =M13+"0:01" -> 0.34930556 | N14: =N13+"0:01" -> 0.39097222 | O14: =O13+"0:01" -> 0.43263889 | P14: =P13+"0:01" -> 0.47430556 | Q14: =Q13+"0:01" -> 0.51597222 | R14: =R13+"0:01" -> 0.55763889 | U14: =U13+"0:01" -> 0.59930556 | X14: =X13+"0:01" -> 0.64097222 | AA14: =AA13+"0:01" -> 0.68263889 | AD14: =AD13+"0:01" -> 0.72430556 | AG14: =AG13+"0:01" -> 0.76597222 | AH14: =AH13+"0:01" -> 0.84930556
A15: 11 | B15: Poštorná,kostel | D15: 0.21875 | E15: =E14+"0:02" -> 0.22569444 | F15: 0.23958333 | G15: 0.26041667 | H15: =H14+"0:02" -> 0.26736111 | I15: 0.28125 | J15: 0.30208333 | K15: =K14+"0:02" -> 0.30902778 | L15: 0.32291667 | M15: =M14+"0:02" -> 0.35069444 | N15: =N14+"0:02" -> 0.39236111 | O15: =O14+"0:02" -> 0.43402778 | P15: =P14+"0:02" -> 0.47569444 | Q15: =Q14+"0:02" -> 0.51736111 | R15: =R14+"0:02" -> 0.55902778 | T15: 0.59375 | U15: =U14+"0:02" -> 0.60069444 | V15: 0.61458333 | W15: 0.63541667 | X15: =X14+"0:02" -> 0.64236111 | Y15: 0.65625 | Z15: 0.67708333 | AA15: =AA14+"0:02" -> 0.68402778 | AB15: 0.69791667 | AC15: 0.71875 | AD15: =AD14+"0:02" -> 0.72569444 | AE15: 0.73958333 | AG15: =AG14+"0:02" -> 0.76736111 | AH15: =AH14+"0:02" -> 0.85069444
A16: 12 | B16: Poštorná,Jana Skácela | D16: =D15+"0:01" -> 0.21944444 | E16: =E15+"0:01" -> 0.22638889 | F16: =F15+"0:01" -> 0.24027778 | G16: =G15+"0:01" -> 0.26111111 | H16: =H15+"0:01" -> 0.26805556 | I16: =I15+"0:01" -> 0.28194444 | J16: =J15+"0:01" -> 0.30277778 | K16: =K15+"0:01" -> 0.30972222 | ... R16: =R15+"0:01" -> 0.55972222 | T16: =T15+"0:01" -> 0.59444444 | U16: =U15+"0:01" -> 0.60138889 | V16: =V15+"0:01" -> 0.61527778 | W16: =W15+"0:01" -> 0.63611111 | X16: =X15+"0:01" -> 0.64305556 | Y16: =Y15+"0:01" -> 0.65694444 | Z16: =Z15+"0:01" -> 0.67777778 | AA16: =AA15+"0:01" -> 0.68472222 | ... AE16: =AE15+"0:01" -> 0.74027778 | AG16: =AG15+"0:01" -> 0.76805556 | AH16: =AH15+"0:01" -> 0.85138889
A17: 13 | B17: Poštorná,Hraniční | D17: =D16+"0:01" -> 0.22013889 | E17: =E16+"0:01" -> 0.22708333 | F17: =F16+"0:01" -> 0.24097222 | G17: =G16+"0:01" -> 0.26180556 | H17: =H16+"0:01" -> 0.26875 | I17: =I16+"0:01" -> 0.28263889 | J17: =J16+"0:01" -> 0.30347222 | K17: =K16+"0:01" -> 0.31041667 | ... R17: =R16+"0:01" -> 0.56041667 | T17: =T16+"0:01" -> 0.59513889 | U17: =U16+"0:01" -> 0.60208333 | V17: =V16+"0:01" -> 0.61597222 | W17: =W16+"0:01" -> 0.63680556 | X17: =X16+"0:01" -> 0.64375 | Y17: =Y16+"0:01" -> 0.65763889 | Z17: =Z16+"0:01" -> 0.67847222 | AA17: =AA16+"0:01" -> 0.68541667 | ... AE17: =AE16+"0:01" -> 0.74097222 | AG17: =AG16+"0:01" -> 0.76875 | AH17: =AH16+"0:01" -> 0.85208333
A18: 14 | B18: Poštorná,FOSFA | C18: příj. | D18: =D17+"0:02" -> 0.22152778 | E18: =E17+"0:02" -> 0.22847222 | F18: =F17+"0:02" -> 0.24236111 | G18: =G17+"0:02" -> 0.26319444 | H18: =H17+"0:02" -> 0.27013889 | I18: =I17+"0:02" -> 0.28402778 | J18: =J17+"0:02" -> 0.30486111 | K18: =K17+"0:02" -> 0.31180556 | ... R18: =R17+"0:02" -> 0.56180556 | T18: =T17+"0:02" -> 0.59652778 | U18: =U17+"0:02" -> 0.60347222 | V18: =V17+"0:01" -> 0.61666667 | W18: =W17+"0:01" -> 0.6375 | X18: =X17+"0:02" -> 0.64513889 | Y18: =Y17+"0:01" -> 0.65833333 | Z18: =Z17+"0:01" -> 0.67916667 | AA18: =AA17+"0:02" -> 0.68680556 | AB18: =AB17+"0:01" -> 0.7 | AC18: =AC17+"0:01" -> 0.72083333 | AD18: =AD17+"0:02" -> 0.72847222 | AE18: =AE17+"0:01" -> 0.74166667 | AG18: =AG17+"0:02" -> 0.77013889 | AH18: =AH17+"0:02" -> 0.85347222
B19: km | D19: 1.8 | E19: 6.9 | F19: 1.8 | G19: 1.8 | H19: 6.9 | I19: 1.8 | J19: 1.8 | K19: 6.9 | L19: 1.8 | M19: 6.9 | N19: 6.9 | O19: 6.9 | P19: 6.9 | Q19: 6.9 | R19: 6.9 | T19: 1.8 | U19: 6.9 | V19: 1.8 | W19: 1.8 | X19: 6.9 | Y19: 1.8 | Z19: 1.8 | AA19: 6.9 | AB19: 1.8 | AC19: 1.8 | AD19: 6.9 | AE19: 1.8 | AG19: 6.9 | AH19: 6.9 | AI19: =SUM(D19:AH19) -> 128.7
A21: Linka číslo 745563 | C21: Poštorná,FOSFA - Poliklinika - Cukrovar - Slovácká - Autobusové nádraží
B23: návrh k projednání | C23: opačný směr
A24: Tč | D24: 2 | E24: =D24+2 -> 4 | F24: =E24+2 -> 6 | G24: =F24+2 -> 8 | H24: =G24+2 -> 10 | I24: =H24+2 -> 12 | J24: =I24+2 -> 14 | K24: =J24+2 -> 16 | L24: =K24+2 -> 18 | ... AH24: =AG24+2 -> 62
A25: 15 | B25: Poštorná,FOSFA | C25: odj. | D25: 0.21597222 | E25: 0.22569444 | F25: 0.23680556 | G25: 0.25763889 | H25: 0.26736111 | I25: 0.27847222 | J25: 0.29930556 | K25: 0.30902778 | L25: 0.32013889 | M25: 0.32986111 | N25: 0.35347222 | O25: 0.39513889 | P25: 0.43680556 | Q25: 0.47847222 | R25: 0.52013889 | S25: 0.56180556 | T25: 0.59097222 | U25: 0.60069444 | V25: 0.61180556 | W25: 0.63263889 | X25: 0.64236111 | Y25: 0.65347222 | Z25: 0.67430556 | AA25: 0.68402778 | AB25: 0.69513889 | AC25: 0.71597222 | AD25: 0.72569444 | AE25: 0.73680556 | AF25: 0.74652778 | AG25: 0.77013889 | AH25: 0.85347222
A26: 14 | B26: Poštorná,Hraniční | D26: =D25+"0:01" -> 0.21666667 | E26: =E25+"0:01" -> 0.22638889 | F26: =F25+"0:01" -> 0.2375 | G26: =G25+"0:01" -> 0.25833333 | H26: =H25+"0:01" -> 0.26805556 | I26: =I25+"0:01" -> 0.27916667 | J26: =J25+"0:01" -> 0.3 | K26: =K25+"0:01" -> 0.30972222 | ... AH26: =AH25+"0:01" -> 0.85416667
A27: 13 | B27: Poštorná,Jana Skácela | D27: =D26+"0:01" -> 0.21736111 | E27: =E26+"0:01" -> 0.22708333 | F27: =F26+"0:01" -> 0.23819444 | G27: =G26+"0:01" -> 0.25902778 | H27: =H26+"0:01" -> 0.26875 | I27: =I26+"0:01" -> 0.27986111 | J27: =J26+"0:01" -> 0.30069444 | K27: =K26+"0:01" -> 0.31041667 | ... AH27: =AH26+"0:01" -> 0.85486111
A28: 12 | B28: Jana Skácela/1. Máje Výstup | C28: příj. | D28: =D27+"0:01" -> 0.21805556 | F28: =F27+"0:01" -> 0.23888889 | G28: =G27+"0:01" -> 0.25972222 | I28: =I27+"0:01" -> 0.28055556 | J28: =J27+"0:01" -> 0.30138889 | L28: =L27+"0:01" -> 0.32222222 | T28: =T27+"0:01" -> 0.59305556 | V28: =V27+"0:01" -> 0.61388889 | W28: =W27+"0:01" -> 0.63472222 | Y28: =Y27+"0:01" -> 0.65555556 | Z28: =Z27+"0:01" -> 0.67638889 | AB28: =AB27+"0:01" -> 0.69722222 | AC28: =AC27+"0:01" -> 0.71805556 | AE28: =AE27+"0:01" -> 0.73888889
A29: 11 | B29: Poštorná , kostel Výstup | C29: příj. | D29: =D28+"0:01" -> 0.21875 | F29: =F28+"0:01" -> 0.23958333 | G29: =G28+"0:01" -> 0.26041667 | I29: =I28+"0:01" -> 0.28125 | J29: =J28+"0:01" -> 0.30208333 | L29: =L28+"0:01" -> 0.32291667 | T29: =T28+"0:01" -> 0.59375 | V29: =V28+"0:01" -> 0.61458333 | W29: =W28+"0:01" -> 0.63541667 | Y29: =Y28+"0:01" -> 0.65625 | Z29: =Z28+"0:01" -> 0.67708333 | AB29: =AB28+"0:01" -> 0.69791667 | AC29: =AC28+"0:01" -> 0.71875 | AE29: =AE28+"0:01" -> 0.73958333
A30: 10 | B30: Poštorná,kostel | C30: odj. | E30: =E27+"0:02" -> 0.22847222 | H30: =H27+"0:02" -> 0.27013889 | K30: =K27+"0:02" -> 0.31180556 | M30: =M27+"0:02" -> 0.33263889 | N30: =N27+"0:02" -> 0.35625 | O30: =O27+"0:02" -> 0.39791667 | P30: =P27+"0:02" -> 0.43958333 | Q30: =Q27+"0:02" -> 0.48125 | R30: =R27+"0:02" -> 0.52291667 | S30: =S27+"0:02" -> 0.56458333 | U30: =U27+"0:02" -> 0.60347222 | X30: =X27+"0:02" -> 0.64513889 | AA30: =AA27+"0:02" -> 0.68680556 | AD30: =AD27+"0:02" -> 0.72847222 | AF30: =AF27+"0:02" -> 0.74930556 | AG30: =AG27+"0:02" -> 0.77291667 | AH30: =AH27+"0:02" -> 0.85625
A31: 9 | B31: Poštorná,Lesní | E31: =E30+"0:01" -> 0.22916667 | H31: =H30+"0:01" -> 0.27083333 | K31: =K30+"0:01" -> 0.3125 | M31: =M30+"0:01" -> 0.33333333 | N31: =N30+"0:01" -> 0.35694444 | O31: =O30+"0:01" -> 0.39861111 | P31: =P30+"0:01" -> 0.44027778 | Q31: =Q30+"0:01" -> 0.48194444 | R31: =R30+"0:01" -> 0.52361111 | S31: =S30+"0:01" -> 0.56527778 | U31: =U30+"0:01" -> 0.60416667 | X31: =X30+"0:01" -> 0.64583333 | AA31: =AA30+"0:01" -> 0.6875 | AD31: =AD30+"0:01" -> 0.72916667 | AF31: =AF30+"0:01" -> 0.75 | AG31: =AG30+"0:01" -> 0.77361111 | AH31: =AH30+"0:01" -> 0.85694444
A32: 8 | B32: Necmonice | E32: =E31+"0:01" -> 0.22986111 | H32: =H31+"0:01" -> 0.27152778 | K32: =K31+"0:01" -> 0.31319444 | M32: =M31+"0:01" -> 0.33402778 | N32: =N31+"0:01" -> 0.35763889 | O32: =O31+"0:01" -> 0.39930556 | P32: =P31+"0:01" -> 0.44097222 | Q32: =Q31+"0:01" -> 0.48263889 | R32: =R31+"0:01" -> 0.52430556 | S32: =S31+"0:01" -> 0.56597222 | U32: =U31+"0:01" -> 0.60486111 | X32: =X31+"0:01" -> 0.64652778 | AA32: =AA31+"0:01" -> 0.68819444 | AD32: =AD31+"0:01" -> 0.72986111 | AF32: =AF31+"0:01" -> 0.75069444 | AG32: =AG31+"0:01" -> 0.77430556 | AH32: =AH31+"0:01" -> 0.85763889
A33: 7 | B33: Dům kultury | E33: =E32+"0:02" -> 0.23125 | H33: =H32+"0:02" -> 0.27291667 | K33: =K32+"0:02" -> 0.31458333 | M33: =M32+"0:02" -> 0.33541667 | N33: =N32+"0:02" -> 0.35902778 | O33: =O32+"0:02" -> 0.40069444 | P33: =P32+"0:02" -> 0.44236111 | Q33: =Q32+"0:02" -> 0.48402778 | R33: =R32+"0:02" -> 0.52569444 | S33: =S32+"0:02" -> 0.56736111 | U33: =U32+"0:02" -> 0.60625 | X33: =X32+"0:02" -> 0.64791667 | AA33: =AA32+"0:02" -> 0.68958333 | AD33: =AD32+"0:02" -> 0.73125 | AF33: =AF32+"0:02" -> 0.75208333 | AG33: =AG32+"0:02" -> 0.77569444 | AH33: =AH32+"0:02" -> 0.85902778
A34: 6 | B34: Nám. TGM, mě. Ú. | E34: =E33+"0:02" -> 0.23263889 | H34: =H33+"0:02" -> 0.27430556 | K34: =K33+"0:02" -> 0.31597222 | M34: =M33+"0:02" -> 0.33680556 | N34: =N33+"0:02" -> 0.36041667 | O34: =O33+"0:02" -> 0.40208333 | P34: =P33+"0:02" -> 0.44375 | Q34: =Q33+"0:02" -> 0.48541667 | R34: =R33+"0:02" -> 0.52708333 | S34: =S33+"0:02" -> 0.56875 | U34: =U33+"0:02" -> 0.60763889 | X34: =X33+"0:02" -> 0.64930556 | AA34: =AA33+"0:02" -> 0.69097222 | AD34: =AD33+"0:02" -> 0.73263889 | AF34: =AF33+"0:02" -> 0.75347222 | AG34: =AG33+"0:02" -> 0.77708333 | AH34: =AH33+"0:02" -> 0.86041667
A35: 5 | B35: Cukrovar | E35: =E34+"0:02" -> 0.23402778 | H35: =H34+"0:02" -> 0.27569444 | K35: =K34+"0:02" -> 0.31736111 | M35: =M34+"0:02" -> 0.33819444 | N35: =N34+"0:02" -> 0.36180556 | O35: =O34+"0:02" -> 0.40347222 | P35: =P34+"0:02" -> 0.44513889 | Q35: =Q34+"0:02" -> 0.48680556 | R35: =R34+"0:02" -> 0.52847222 | S35: =S34+"0:02" -> 0.57013889 | U35: =U34+"0:02" -> 0.60902778 | X35: =X34+"0:02" -> 0.65069444 | AA35: =AA34+"0:02" -> 0.69236111 | AD35: =AD34+"0:02" -> 0.73402778 | AF35: =AF34+"0:02" -> 0.75486111 | AG35: =AG34+"0:02" -> 0.77847222 | AH35: =AH34+"0:02" -> 0.86180556
A36: 4 | B36: Sovadinova | E36: =E35+"0:02" -> 0.23541667 | H36: =H35+"0:02" -> 0.27708333 | K36: =K35+"0:02" -> 0.31875 | M36: =M35+"0:02" -> 0.33958333 | N36: =N35+"0:02" -> 0.36319444 | O36: =O35+"0:02" -> 0.40486111 | P36: =P35+"0:02" -> 0.44652778 | Q36: =Q35+"0:02" -> 0.48819444 | R36: =R35+"0:02" -> 0.52986111 | S36: =S35+"0:02" -> 0.57152778 | U36: =U35+"0:02" -> 0.61041667 | X36: =X35+"0:02" -> 0.65208333 | AA36: =AA35+"0:02" -> 0.69375 | AD36: =AD35+"0:02" -> 0.73541667 | AF36: =AF35+"0:02" -> 0.75625 | AG36: =AG35+"0:02" -> 0.77986111 | AH36: =AH35+"0:02" -> 0.86319444
A37: 3 | B37: Slovácká | E37: =E36+"0:02" -> 0.23680556 | H37: =H36+"0:02" -> 0.27847222 | K37: =K36+"0:02" -> 0.32013889 | M37: =M36+"0:02" -> 0.34097222 | N37: =N36+"0:02" -> 0.36458333 | O37: =O36+"0:02" -> 0.40625 | P37: =P36+"0:02" -> 0.44791667 | Q37: =Q36+"0:02" -> 0.48958333 | R37: =R36+"0:02" -> 0.53125 | S37: =S36+"0:02" -> 0.57291667 | U37: =U36+"0:02" -> 0.61180556 | X37: =X36+"0:02" -> 0.65347222 | AA37: =AA36+"0:02" -> 0.69513889 | AD37: =AD36+"0:02" -> 0.73680556 | AF37: =AF36+"0:02" -> 0.75763889 | AG37: =AG36+"0:02" -> 0.78125 | AH37: =AH36+"0:02" -> 0.86458333
A38: 2 | B38: Jana Palacha | E38: =E37+"0:02" -> 0.23819444 | H38: =H37+"0:02" -> 0.27986111 | K38: =K37+"0:02" -> 0.32152778 | M38: =M37+"0:02" -> 0.34236111 | N38: =N37+"0:02" -> 0.36597222 | O38: =O37+"0:02" -> 0.40763889 | P38: =P37+"0:02" -> 0.44930556 | Q38: =Q37+"0:02" -> 0.49097222 | R38: =R37+"0:02" -> 0.53263889 | S38: =S37+"0:02" -> 0.57430556 | U38: =U37+"0:02" -> 0.61319444 | X38: =X37+"0:02" -> 0.65486111 | AA38: =AA37+"0:02" -> 0.69652778 | AD38: =AD37+"0:02" -> 0.73819444 | AF38: =AF37+"0:02" -> 0.75902778 | AG38: =AG37+"0:02" -> 0.78263889 | AH38: =AH37+"0:02" -> 0.86597222
A39: 1 | B39: Autobusové nádraží | C39: příj. | E39: =E38+"0:03" -> 0.24027778 | H39: =H38+"0:03" -> 0.28194444 | K39: =K38+"0:03" -> 0.32361111 | M39: =M38+"0:03" -> 0.34444444 | N39: =N38+"0:03" -> 0.36805556 | O39: =O38+"0:03" -> 0.40972222 | P39: =P38+"0:03" -> 0.45138889 | Q39: =Q38+"0:03" -> 0.49305556 | R39: =R38+"0:03" -> 0.53472222 | S39: =S38+"0:03" -> 0.57638889 | U39: =U38+"0:03" -> 0.61527778 | X39: =X38+"0:03" -> 0.65694444 | AA39: =AA38+"0:03" -> 0.69861111 | AD39: =AD38+"0:03" -> 0.74027778 | AF39: =AF38+"0:03" -> 0.76111111 | AG39: =AG38+"0:03" -> 0.78472222 | AH39: =AH38+"0:03" -> 0.86805556
B40: km | D40: 1.8 | E40: 6.9 | F40: 1.8 | G40: 1.8 | H40: 6.9 | I40: 1.8 | J40: 1.8 | K40: 6.9 | L40: 1.8 | M40: 6.9 | N40: 6.9 | O40: 6.9 | P40: 6.9 | Q40: 6.9 | R40: 6.9 | S40: 6.9 | T40: 1.8 | U40: 6.9 | V40: 1.8 | W40: 1.8 | X40: 6.9 | Y40: 1.8 | Z40: 1.8 | AA40: 6.9 | AB40: 1.8 | AC40: 1.8 | AD40: 6.9 | AE40: 1.8 | AF40: 6.9 | AG40: 6.9 | AH40: 6.9 | AI40: =SUM(D40:AD40) -> 120

Sheet 565 
A1: Linka číslo 745565 | D1: Městský hřbitov-Sovadinova-Stará Břeclav
B3: návrh k projednání
A4: Tč | D4: 1 | E4: 3 | F4: =E4+2 -> 5 | G4: =F4+2 -> 7 | H4: =G4+2 -> 9 | I4: =H4+2 -> 11 | J4: =I4+2 -> 13 | K4: =J4+2 -> 15 | L4: =K4+2 -> 17 | M4: =L4+2 -> 19 | ... V4: =U4+2 -> 37
A5: 1 | B5: Městský hřbitov | C5: odj.
A6: 2 | B6: Lanžhotská
A7: 3 | B7: Pohansko rozc.
A8: 4 | B8: Gumotex
A9: 5 | B9: BORS
A10: 6 | B10: Autobusové nádraží | D10: 0.19027778 | E10: 0.22361111 | F10: 0.26527778 | G10: 0.30694444 | H10: 0.34861111 | I10: 0.39027778 | J10: 0.43194444 | K10: 0.47361111 | L10: 0.51527778 | M10: 0.55694444 | N10: 0.59861111 | O10: 0.64027778 | P10: 0.68194444 | Q10: 0.72361111 | R10: 0.76527778 | S10: 0.80694444 | T10: 0.84861111 | U10: 0.89027778 | V10: 0.93194444
A11: 7 | B11: Jana Palacha | D11: =D10+"0:03" -> 0.19236111 | E11: =E10+"0:03" -> 0.22569444 | F11: =F10+"0:03" -> 0.26736111 | G11: =G10+"0:03" -> 0.30902778 | H11: =H10+"0:03" -> 0.35069444 | I11: =I10+"0:03" -> 0.39236111 | J11: =J10+"0:03" -> 0.43402778 | K11: =K10+"0:03" -> 0.47569444 | ... U11: =U10+"0:03" -> 0.89236111 | V11: =V10+"0:02" -> 0.93333333
A12: 8 | B12: Slovácká | D12: =D11+"0:02" -> 0.19375 | E12: =E11+"0:02" -> 0.22708333 | F12: =F11+"0:02" -> 0.26875 | G12: =G11+"0:02" -> 0.31041667 | H12: =H11+"0:02" -> 0.35208333 | I12: =I11+"0:02" -> 0.39375 | J12: =J11+"0:02" -> 0.43541667 | K12: =K11+"0:02" -> 0.47708333 | ... V12: =V11+"0:02" -> 0.93472222
A13: 9 | B13: Sovadinova | D13: =D12+"0:02" -> 0.19513889 | E13: =E12+"0:02" -> 0.22847222 | F13: =F12+"0:02" -> 0.27013889 | G13: =G12+"0:02" -> 0.31180556 | H13: =H12+"0:02" -> 0.35347222 | I13: =I12+"0:02" -> 0.39513889 | J13: =J12+"0:02" -> 0.43680556 | K13: =K12+"0:02" -> 0.47847222 | ... U13: =U12+"0:02" -> 0.89513889 | V13: =V12+"0:01" -> 0.93541667
A14: 10 | B14: Stará Břeclav, Lidická | D14: =D13+"0:02" -> 0.19652778 | E14: =E13+"0:02" -> 0.22986111 | F14: =F13+"0:02" -> 0.27152778 | G14: =G13+"0:02" -> 0.31319444 | H14: =H13+"0:02" -> 0.35486111 | I14: =I13+"0:02" -> 0.39652778 | J14: =J13+"0:02" -> 0.43819444 | K14: =K13+"0:02" -> 0.47986111 | ... U14: =U13+"0:02" -> 0.89652778 | V14: =V13+"0:01" -> 0.93611111
A15: 11 | B15: Stará Břeclav, Skopalíkova | D15: =D14+"0:01" -> 0.19722222 | E15: =E14+"0:01" -> 0.23055556 | F15: =F14+"0:01" -> 0.27222222 | G15: =G14+"0:01" -> 0.31388889 | H15: =H14+"0:01" -> 0.35555556 | I15: =I14+"0:01" -> 0.39722222 | J15: =J14+"0:01" -> 0.43888889 | K15: =K14+"0:01" -> 0.48055556 | ... V15: =V14+"0:01" -> 0.93680556
A16: 12 | B16: Stará Břeclav, Vinohradní | D16: =D15+"0:01" -> 0.19791667 | E16: =E15+"0:01" -> 0.23125 | F16: =F15+"0:01" -> 0.27291667 | G16: =G15+"0:01" -> 0.31458333 | H16: =H15+"0:01" -> 0.35625 | I16: =I15+"0:01" -> 0.39791667 | J16: =J15+"0:01" -> 0.43958333 | K16: =K15+"0:01" -> 0.48125 | ... V16: =V15+"0:01" -> 0.9375
A17: 13 | B17: Stará Břeclav, Mánesova | D17: ~ | E17: ~ | F17: ~ | G17: ~ | H17: ~ | I17: ~ | J17: ~ | K17: ~ | L17: ~ | M17: ~ | N17: ~ | O17: ~ | P17: ~ | Q17: ~ | R17: ~ | S17: ~ | T17: ~ | U17: ~ | V17: ~
A18: 14 | B18: Stará Břeclav, kult.dům | D18: ~ | E18: ~ | F18: ~ | G18: ~ | H18: ~ | I18: ~ | J18: ~ | K18: ~ | L18: ~ | M18: ~ | N18: ~ | O18: ~ | P18: ~ | Q18: ~ | R18: ~ | S18: ~ | T18: ~ | U18: ~ | V18: ~
A19: 15 | B19: Stará Břeclav, u parku | D19: ~ | E19: ~ | F19: ~ | G19: ~ | H19: ~ | I19: ~ | J19: ~ | K19: ~ | L19: ~ | M19: ~ | N19: ~ | O19: ~ | P19: ~ | Q19: ~ | R19: ~ | S19: ~ | T19: ~ | U19: ~ | V19: ~
A20: 16 | B20: Stará Břeclav, J.Moláka | D20: ~ | E20: ~ | F20: ~ | G20: ~ | H20: ~ | I20: ~ | J20: ~ | K20: ~ | L20: ~ | M20: ~ | N20: ~ | O20: ~ | P20: ~ | Q20: ~ | R20: ~ | S20: ~ | T20: ~ | U20: ~ | V20: ~
A21: 17 | B21: Stará Břeclav, křiž.Ladná | C21: příj. | D21: =D16+"0:02" -> 0.19930556 | E21: =E16+"0:02" -> 0.23263889 | F21: =F16+"0:02" -> 0.27430556 | G21: =G16+"0:02" -> 0.31597222 | H21: =H16+"0:02" -> 0.35763889 | I21: =I16+"0:02" -> 0.39930556 | J21: =J16+"0:02" -> 0.44097222 | K21: =K16+"0:02" -> 0.48263889 | ... V21: =V16+"0:02" -> 0.93888889
B22: km | D22: 4.2 | E22: 4.2 | F22: 4.2 | G22: 4.2 | H22: 4.2 | I22: 4.2 | J22: 4.2 | K22: 4.2 | L22: 4.2 | M22: 4.2 | N22: 4.2 | O22: 4.2 | P22: 4.2 | Q22: 4.2 | R22: 4.2 | S22: 4.2 | T22: 4.2 | U22: 4.2 | V22: 4.2 | W22: =SUM(D22:V22) -> 79.8
A41: Linka číslo 745565 | C41: Stará Břeclav - Sovadinova - Městský Hřbitov
B43: návrh k projednání | C43: opačný směr
A44: Tč | D44: 2 | E44: =D44+2 -> 4 | F44: =E44+2 -> 6 | G44: =F44+2 -> 8 | H44: =G44+2 -> 10 | I44: =H44+2 -> 12 | J44: =I44+2 -> 14 | K44: =J44+2 -> 16 | L44: =K44+2 -> 18 | ... V44: =U44+2 -> 38
A45: 17 | B45: Stará Břeclav, křiž.Ladná | C45: odj. | D45: 0.19930556 | E45: 0.24097222 | F45: 0.28263889 | G45: 0.32430556 | H45: 0.36597222 | I45: 0.40763889 | J45: 0.44930556 | K45: 0.49097222 | L45: 0.53263889 | M45: 0.57430556 | N45: 0.61597222 | O45: 0.65763889 | P45: 0.69930556 | Q45: 0.74097222 | R45: 0.78263889 | S45: 0.82430556 | T45: 0.86597222 | U45: 0.90763889 | V45: 0.93888889
A46: 16 | B46: Stará Břeclav, J.Moláka | D46: =D45+"0:01" -> 0.2 | E46: =E45+"0:01" -> 0.24166667 | F46: =F45+"0:01" -> 0.28333333 | G46: =G45+"0:01" -> 0.325 | H46: =H45+"0:01" -> 0.36666667 | I46: =I45+"0:01" -> 0.40833333 | J46: =J45+"0:01" -> 0.45 | K46: =K45+"0:01" -> 0.49166667 | ... V46: =V45+"0:01" -> 0.93958333
A47: 15 | B47: Stará Břeclav, u parku
A48: 14 | B48: Stará Břeclav, kult.dům
A49: 13 | B49: Stará Břeclav, Mánesova
A50: 12 | B50: Stará Břeclav, Vinohradní | D50: =D46+"0:01" -> 0.20069444 | E50: =E46+"0:01" -> 0.24236111 | F50: =F46+"0:01" -> 0.28402778 | G50: =G46+"0:01" -> 0.32569444 | H50: =H46+"0:01" -> 0.36736111 | I50: =I46+"0:01" -> 0.40902778 | J50: =J46+"0:01" -> 0.45069444 | K50: =K46+"0:01" -> 0.49236111 | ... V50: =V46+"0:01" -> 0.94027778
A51: 11 | B51: Stará Břeclav, Skopalíkova | D51: =D50+"0:01" -> 0.20138889 | E51: =E50+"0:01" -> 0.24305556 | F51: =F50+"0:01" -> 0.28472222 | G51: =G50+"0:01" -> 0.32638889 | H51: =H50+"0:01" -> 0.36805556 | I51: =I50+"0:01" -> 0.40972222 | J51: =J50+"0:01" -> 0.45138889 | K51: =K50+"0:01" -> 0.49305556 | ... V51: =V50+"0:01" -> 0.94097222
A52: 10 | B52: Stará Břeclav, Lidická | D52: =D51+"0:02" -> 0.20277778 | E52: =E51+"0:02" -> 0.24444444 | F52: =F51+"0:02" -> 0.28611111 | G52: =G51+"0:02" -> 0.32777778 | H52: =H51+"0:02" -> 0.36944444 | I52: =I51+"0:02" -> 0.41111111 | J52: =J51+"0:02" -> 0.45277778 | K52: =K51+"0:02" -> 0.49444444 | ... V52: =V51+"0:02" -> 0.94236111
A53: 9 | B53: Sovadinova | D53: =D52+"0:02" -> 0.20416667 | E53: =E52+"0:02" -> 0.24583333 | F53: =F52+"0:02" -> 0.2875 | G53: =G52+"0:02" -> 0.32916667 | H53: =H52+"0:02" -> 0.37083333 | I53: =I52+"0:02" -> 0.4125 | J53: =J52+"0:02" -> 0.45416667 | K53: =K52+"0:02" -> 0.49583333 | ... V53: =V52+"0:02" -> 0.94375
A54: 8 | B54: Slovácká | D54: =D53+"0:01" -> 0.20486111 | E54: =E53+"0:01" -> 0.24652778 | F54: =F53+"0:01" -> 0.28819444 | G54: =G53+"0:01" -> 0.32986111 | H54: =H53+"0:01" -> 0.37152778 | I54: =I53+"0:01" -> 0.41319444 | J54: =J53+"0:01" -> 0.45486111 | K54: =K53+"0:01" -> 0.49652778 | ... V54: =V53+"0:01" -> 0.94444444
A55: 7 | B55: Jana Palacha | D55: =D54+"0:02" -> 0.20625 | E55: =E54+"0:02" -> 0.24791667 | F55: =F54+"0:02" -> 0.28958333 | G55: =G54+"0:02" -> 0.33125 | H55: =H54+"0:02" -> 0.37291667 | I55: =I54+"0:02" -> 0.41458333 | J55: =J54+"0:02" -> 0.45625 | K55: =K54+"0:02" -> 0.49791667 | ... V55: =V54+"0:02" -> 0.94583333
A56: 6 | B56: Autobusové nádraží | D56: =D55+"0:03" -> 0.20833333 | E56: =E55+"0:03" -> 0.25 | F56: =F55+"0:03" -> 0.29166667 | G56: =G55+"0:03" -> 0.33333333 | H56: =H55+"0:03" -> 0.375 | I56: =I55+"0:03" -> 0.41666667 | J56: =J55+"0:03" -> 0.45833333 | K56: =K55+"0:03" -> 0.5 | ... V56: =V55+"0:03" -> 0.94791667
A57: 5 | B57: BORS
A58: 3 | B58: Pohansko rozc.
A59: 4 | B59: Gumotex
A60: 3 | B60: Pohansko rozc.
...

Sheet 566 
A1: Linka číslo 745566 | D1: Křižovatka Ladná - Sovadinova - Aut. Nádraží - Nám. TGM - Valtická Točna
B2: návrh k projednání
A3: Tč | D3: 1 | E3: =D3+2 -> 3 | F3: =E3+2 -> 5 | G3: =F3+2 -> 7 | H3: =G3+2 -> 9 | I3: =H3+2 -> 11 | J3: =I3+2 -> 13 | K3: =J3+2 -> 15 | L3: =K3+2 -> 17 | ... U3: =T3+2 -> 35
A4: 1 | B4: Křižovatka Ladná | C4: odj. | D4: 0.21180556 | E4: 0.25347222 | F4: 0.29513889 | G4: 0.33680556 | H4: 0.37847222 | I4: 0.42013889 | J4: 0.46180556 | K4: 0.50347222 | L4: 0.54513889 | M4: 0.58680556 | N4: 0.62847222 | O4: 0.67013889 | P4: 0.71180556 | Q4: 0.75347222 | R4: 0.79513889 | S4: 0.83680556 | T4: 0.87847222 | U4: 0.92013889
A5: 2 | B5: Jana Moláka x | D5: =D4+"0:01" -> 0.2125 | E5: =E4+"0:01" -> 0.25416667 | F5: =F4+"0:01" -> 0.29583333 | G5: =G4+"0:01" -> 0.3375 | H5: =H4+"0:01" -> 0.37916667 | I5: =I4+"0:01" -> 0.42083333 | J5: =J4+"0:01" -> 0.4625 | K5: =K4+"0:01" -> 0.50416667 | ... U5: =U4+"0:01" -> 0.92083333
A6: 3 | B6: Vinohradní | D6: =D5+"0:01" -> 0.21319444 | E6: =E5+"0:01" -> 0.25486111 | F6: =F5+"0:01" -> 0.29652778 | G6: =G5+"0:01" -> 0.33819444 | H6: =H5+"0:01" -> 0.37986111 | I6: =I5+"0:01" -> 0.42152778 | J6: =J5+"0:01" -> 0.46319444 | K6: =K5+"0:01" -> 0.50486111 | ... U6: =U5+"0:01" -> 0.92152778
A7: 4 | B7: Stará Břeclav, u Parku | D7: =D6+"0:01" -> 0.21388889 | E7: =E6+"0:01" -> 0.25555556 | F7: =F6+"0:01" -> 0.29722222 | G7: =G6+"0:01" -> 0.33888889 | H7: =H6+"0:01" -> 0.38055556 | I7: =I6+"0:01" -> 0.42222222 | J7: =J6+"0:01" -> 0.46388889 | K7: =K6+"0:01" -> 0.50555556 | ... U7: =U6+"0:01" -> 0.92222222
A8: 5 | B8: Stará Břeclav, DK | D8: =D7+"0:01" -> 0.21458333 | E8: =E7+"0:01" -> 0.25625 | F8: =F7+"0:01" -> 0.29791667 | G8: =G7+"0:01" -> 0.33958333 | H8: =H7+"0:01" -> 0.38125 | I8: =I7+"0:01" -> 0.42291667 | J8: =J7+"0:01" -> 0.46458333 | K8: =K7+"0:01" -> 0.50625 | ... U8: =U7+"0:01" -> 0.92291667
A9: 6 | B9: Mánesova | D9: =D8+"0:01" -> 0.21527778 | E9: =E8+"0:01" -> 0.25694444 | F9: =F8+"0:01" -> 0.29861111 | G9: =G8+"0:01" -> 0.34027778 | H9: =H8+"0:01" -> 0.38194444 | I9: =I8+"0:01" -> 0.42361111 | J9: =J8+"0:01" -> 0.46527778 | K9: =K8+"0:01" -> 0.50694444 | ... U9: =U8+"0:01" -> 0.92361111
A10: 7 | B10: Lidická | D10: =D9+"0:02" -> 0.21666667 | E10: =E9+"0:02" -> 0.25833333 | F10: =F9+"0:02" -> 0.3 | G10: =G9+"0:02" -> 0.34166667 | H10: =H9+"0:02" -> 0.38333333 | I10: =I9+"0:02" -> 0.425 | J10: =J9+"0:02" -> 0.46666667 | K10: =K9+"0:02" -> 0.50833333 | ... U10: =U9+"0:02" -> 0.925
A11: 8 | B11: Sovadinova | D11: =D10+"0:03" -> 0.21875 | E11: =E10+"0:03" -> 0.26041667 | F11: =F10+"0:03" -> 0.30208333 | G11: =G10+"0:03" -> 0.34375 | H11: =H10+"0:03" -> 0.38541667 | I11: =I10+"0:03" -> 0.42708333 | J11: =J10+"0:03" -> 0.46875 | K11: =K10+"0:03" -> 0.51041667 | ... U11: =U10+"0:03" -> 0.92708333
A12: 9 | B12: Městský hřbitov
A13: 10 | B13: Lanžhotská
A14: 11 | B14: Pohansko rozc.
A15: 12 | B15: Gumotex
A16: 13 | B16: Pohansko rozc.
A17: 14 | B17: BORS
A18: 15 | B18: Autobusové nádraží | C18: příj. | D18: =D11+"0:03" -> 0.22083333 | E18: =E11+"0:03" -> 0.2625 | F18: =F11+"0:03" -> 0.30416667 | G18: =G11+"0:03" -> 0.34583333 | H18: =H11+"0:03" -> 0.3875 | I18: =I11+"0:03" -> 0.42916667 | J18: =J11+"0:03" -> 0.47083333 | K18: =K11+"0:03" -> 0.5125 | ... U18: =U11+"0:03" -> 0.92916667
A19: 16 | B19: Autobusové nádraží | C19: odj. | D19: =D18+"0:03" -> 0.22291667 | E19: =E18+"0:03" -> 0.26458333 | F19: =F18+"0:03" -> 0.30625 | G19: =G18+"0:03" -> 0.34791667 | H19: =H18+"0:03" -> 0.38958333 | I19: =I18+"0:03" -> 0.43125 | J19: =J18+"0:03" -> 0.47291667 | K19: =K18+"0:03" -> 0.51458333 | ... S19: =S18+"0:03" -> 0.84791667
A20: 17 | B20: Jana Palacha | D20: =D19+"0:03" -> 0.225 | E20: =E19+"0:03" -> 0.26666667 | F20: =F19+"0:03" -> 0.30833333 | G20: =G19+"0:03" -> 0.35 | H20: =H19+"0:03" -> 0.39166667 | I20: =I19+"0:03" -> 0.43333333 | J20: =J19+"0:03" -> 0.475 | K20: =K19+"0:03" -> 0.51666667 | ... S20: =S19+"0:03" -> 0.85
A21: 18 | B21: nám.TGM kostel | D21: =D20+"0:03" -> 0.22708333 | E21: =E20+"0:03" -> 0.26875 | F21: =F20+"0:03" -> 0.31041667 | G21: =G20+"0:03" -> 0.35208333 | H21: =H20+"0:03" -> 0.39375 | I21: =I20+"0:03" -> 0.43541667 | J21: =J20+"0:03" -> 0.47708333 | K21: =K20+"0:03" -> 0.51875 | ... S21: =S20+"0:03" -> 0.85208333
A22: 19 | B22: Poštorná,Lesní | D22: =D21+"0:02" -> 0.22847222 | E22: =E21+"0:02" -> 0.27013889 | F22: =F21+"0:02" -> 0.31180556 | G22: =G21+"0:02" -> 0.35347222 | H22: =H21+"0:02" -> 0.39513889 | I22: =I21+"0:02" -> 0.43680556 | J22: =J21+"0:02" -> 0.47847222 | K22: =K21+"0:02" -> 0.52013889 | ... S22: =S21+"0:02" -> 0.85347222
A23: 20 | B23: Poštorná,kostel | D23: =D22+"0:01" -> 0.22916667 | E23: =E22+"0:01" -> 0.27083333 | F23: =F22+"0:01" -> 0.3125 | G23: =G22+"0:01" -> 0.35416667 | H23: =H22+"0:01" -> 0.39583333 | I23: =I22+"0:01" -> 0.4375 | J23: =J22+"0:01" -> 0.47916667 | K23: =K22+"0:01" -> 0.52083333 | ... S23: =S22+"0:01" -> 0.85416667
A24: 21 | B24: Poštorná,Nádražní | D24: =D23+"0:02" -> 0.23055556 | E24: =E23+"0:02" -> 0.27222222 | F24: =F23+"0:02" -> 0.31388889 | G24: =G23+"0:02" -> 0.35555556 | H24: =H23+"0:02" -> 0.39722222 | I24: =I23+"0:02" -> 0.43888889 | J24: =J23+"0:02" -> 0.48055556 | K24: =K23+"0:02" -> 0.52222222 | ... S24: =S23+"0:02" -> 0.85555556
A25: 22 | B25: Poštorná,PKZ | D25: =D24+"0:01" -> 0.23125 | E25: =E24+"0:01" -> 0.27291667 | F25: =F24+"0:01" -> 0.31458333 | G25: =G24+"0:01" -> 0.35625 | H25: =H24+"0:01" -> 0.39791667 | I25: =I24+"0:01" -> 0.43958333 | J25: =J24+"0:01" -> 0.48125 | K25: =K24+"0:01" -> 0.52291667 | ... S25: =S24+"0:01" -> 0.85625
A26: 23 | B26: Poštorná,Tovární čtvrť | D26: =D25+"0:01" -> 0.23194444 | E26: =E25+"0:01" -> 0.27361111 | F26: =F25+"0:01" -> 0.31527778 | G26: =G25+"0:01" -> 0.35694444 | H26: =H25+"0:01" -> 0.39861111 | I26: =I25+"0:01" -> 0.44027778 | J26: =J25+"0:01" -> 0.48194444 | K26: =K25+"0:01" -> 0.52361111 | ... S26: =S25+"0:01" -> 0.85694444
A27: 24 | B27: Poštorná,Hlavní | D27: ~ | E27: ~ | F27: ~ | G27: ~ | H27: ~ | I27: ~ | J27: ~ | K27: ~ | L27: ~ | M27: ~ | N27: ~ | O27: ~ | P27: ~ | Q27: ~ | R27: ~ | S27: ~
A28: 25 | B28: Poštorná,Valtická | D28: ~ | E28: ~ | F28: ~ | G28: ~ | H28: ~ | I28: ~ | J28: ~ | K28: ~ | L28: ~ | M28: ~ | N28: ~ | O28: ~ | P28: ~ | Q28: ~ | R28: ~ | S28: ~
A29: 26 | B29: Poštorná,Valtická točna | C29: příj. | D29: =D26+"0:02" -> 0.23333333 | E29: =E26+"0:02" -> 0.275 | F29: =F26+"0:02" -> 0.31666667 | G29: =G26+"0:02" -> 0.35833333 | H29: =H26+"0:02" -> 0.4 | I29: =I26+"0:02" -> 0.44166667 | J29: =J26+"0:02" -> 0.48333333 | K29: =K26+"0:02" -> 0.525 | ... S29: =S26+"0:02" -> 0.85833333
B30: km | D30: 9.5 | E30: 9.5 | F30: 9.5 | G30: 9.5 | H30: 9.5 | I30: 9.5 | J30: 9.5 | K30: 9.5 | L30: 9.5 | M30: 9.5 | N30: 9.5 | O30: 9.5 | P30: 9.5 | Q30: 9.5 | R30: 9.5 | S30: 9.5 | T30: 4.9 | U30: 4.9 | V30: =SUM(C30:U30) -> 161.8
A34: Linka číslo 745566 | E34: Valtická Točna - Aut. Nádraží - Sovadinova - Křižovatka Ladná
B35: návrh k projednání
A36: Tč | D36: 2 | E36: =D36+2 -> 4 | F36: =E36+2 -> 6 | G36: =F36+2 -> 8 | H36: =G36+2 -> 10 | I36: =H36+2 -> 12 | J36: =I36+2 -> 14 | K36: =J36+2 -> 16 | L36: =K36+2 -> 18 | ... AA36: =Z36+2 -> 48
A37: 22 | B37: Poštorná,Valtická točna | C37: odj. | D37: 0.22222222 | E37: 0.25 | F37: 0.26388889 | G37: 0.29166667 | H37: 0.30555556 | I37: 0.31180556 | J37: 0.34722222 | K37: 0.38888889 | L37: 0.43055556 | M37: 0.47222222 | N37: 0.51388889 | O37: 0.55555556 | P37: 0.59722222 | Q37: 0.625 | R37: 0.63888889 | S37: 0.66666667 | T37: 0.68055556 | U37: 0.70833333 | V37: 0.72222222 | W37: 0.75 | X37: 0.76388889
A38: 21 | B38: Poštorná, Tovární čtvrt | D38: =D37+"0:02" -> 0.22361111 | E38: =E37+"0:02" -> 0.25138889 | F38: =F37+"0:02" -> 0.26527778 | G38: =G37+"0:02" -> 0.29305556 | H38: =H37+"0:02" -> 0.30694444 | I38: =I37+"0:02" -> 0.31319444 | J38: =J37+"0:02" -> 0.34861111 | K38: =K37+"0:02" -> 0.39027778 | ... X38: =X37+"0:02" -> 0.76527778
A39: 20 | B39: Poštoná, PKZ | D39: =D38+"0:02" -> 0.225 | E39: =E38+"0:02" -> 0.25277778 | F39: =F38+"0:02" -> 0.26666667 | G39: =G38+"0:02" -> 0.29444444 | H39: =H38+"0:02" -> 0.30833333 | I39: =I38+"0:02" -> 0.31458333 | J39: =J38+"0:02" -> 0.35 | K39: =K38+"0:02" -> 0.39166667 | ... X39: =X38+"0:02" -> 0.76666667
A40: 19 | B40: Poštorná, Nádražní | D40: =D39+"0:01" -> 0.22569444 | E40: =E39+"0:01" -> 0.25347222 | F40: =F39+"0:01" -> 0.26736111 | G40: =G39+"0:01" -> 0.29513889 | H40: =H39+"0:01" -> 0.30902778 | I40: =I39+"0:01" -> 0.31527778 | J40: =J39+"0:01" -> 0.35069444 | K40: =K39+"0:01" -> 0.39236111 | ... X40: =X39+"0:01" -> 0.76736111
A41: 18 | B41: Poštorná,kostel | D41: =D40+"0:01" -> 0.22638889 | E41: =E40+"0:01" -> 0.25416667 | F41: =F40+"0:01" -> 0.26805556 | G41: =G40+"0:01" -> 0.29583333 | H41: =H40+"0:01" -> 0.30972222 | I41: =I40+"0:01" -> 0.31597222 | J41: =J40+"0:01" -> 0.35138889 | K41: =K40+"0:01" -> 0.39305556 | ... X41: =X40+"0:01" -> 0.76805556
A42: 17 | B42: Poštorná,Lesní | D42: =D41+"0:01" -> 0.22708333 | E42: =E41+"0:01" -> 0.25486111 | F42: =F41+"0:01" -> 0.26875 | G42: =G41+"0:01" -> 0.29652778 | H42: =H41+"0:01" -> 0.31041667 | I42: =I41+"0:01" -> 0.31666667 | J42: =J41+"0:01" -> 0.35208333 | K42: =K41+"0:01" -> 0.39375 | ... X42: =X41+"0:01" -> 0.76875
A43: 16 | B43: nám.TGM kostel | D43: =D42+"0:02" -> 0.22847222 | E43: =E42+"0:02" -> 0.25625 | F43: =F42+"0:02" -> 0.27013889 | G43: =G42+"0:02" -> 0.29791667 | H43: =H42+"0:02" -> 0.31180556 | I43: =I42+"0:02" -> 0.31805556 | J43: =J42+"0:02" -> 0.35347222 | K43: =K42+"0:02" -> 0.39513889 | ... X43: =X42+"0:02" -> 0.77013889
...

Sheet 567 
A1: Linka číslo 745567 | D1: Autobusové nádraží-Hlavní - Valtická Točna
B3: návrh k projednání
A4: Tč | D4: 1 | E4: =D4+2 -> 3 | F4: =E4+2 -> 5 | G4: =F4+2 -> 7 | H4: =G4+2 -> 9 | I4: =H4+2 -> 11 | J4: =I4+2 -> 13 | K4: =J4+2 -> 15 | L4: =K4+2 -> 17 | ... AO4: =AN4+2 -> 75
A5: 1 | B5: Městský Hřbitov | C5: odj. | D5: 0.18541667 | F5: 0.22708333 | I5: 0.26875 | M5: 0.31041667 | AA5: 0.60208333 | AD5: 0.64375 | AG5: 0.68541667 | AJ5: 0.72708333
A6: 2 | B6: Pohansko rozc. | D6: =D5+"0:01" -> 0.18611111 | F6: =F5+"0:01" -> 0.22777778 | I6: =I5+"0:01" -> 0.26944444 | M6: =M5+"0:01" -> 0.31111111 | AA6: =AA5+"0:01" -> 0.60277778 | AD6: =AD5+"0:01" -> 0.64444444 | AG6: =AG5+"0:01" -> 0.68611111 | AJ6: =AJ5+"0:01" -> 0.72777778
A7: 3 | B7: Gumotex | D7: =D6+"0:02" -> 0.1875 | F7: =F6+"0:02" -> 0.22916667 | I7: =I6+"0:02" -> 0.27083333 | M7: =M6+"0:02" -> 0.3125 | AA7: =AA6+"0:02" -> 0.60416667 | AD7: =AD6+"0:02" -> 0.64583333 | AG7: =AG6+"0:02" -> 0.6875 | AJ7: =AJ6+"0:02" -> 0.72916667
A8: 4 | B8: Autobusové nádraží | C8: příj. | D8: =D7+"0:03" -> 0.18958333 | F8: =F7+"0:03" -> 0.23125 | I8: =I7+"0:03" -> 0.27291667 | M8: =M7+"0:03" -> 0.31458333 | AA8: =AA7+"0:03" -> 0.60625 | AD8: =AD7+"0:03" -> 0.64791667 | AG8: =AG7+"0:03" -> 0.68958333 | AJ8: =AJ7+"0:03" -> 0.73125
A9: 5 | B9: Autobusové nádraží | C9: odj. | D9: =D8 -> 0.18958333 | E9: 0.21180556 | F9: =F8 -> 0.23125 | G9: 0.23958333 | H9: 0.25347222 | I9: =I8 -> 0.27291667 | J9: 0.28125 | K9: 0.29513889 | L9: 0.30208333 | M9: =M8 -> 0.31458333 | N9: 0.33680556 | O9: 0.35625 | P9: 0.37847222 | Q9: 0.39791667 | R9: 0.42013889 | S9: 0.43958333 | T9: 0.46180556 | U9: 0.48125 | V9: 0.50347222 | W9: 0.52291667 | X9: 0.54513889 | Y9: 0.56458333 | Z9: 0.58680556 | AA9: 0.60625 | AB9: 0.61458333 | AC9: 0.62847222 | AD9: 0.64791667 | AE9: 0.65625 | AF9: 0.67013889 | AG9: 0.68958333 | AH9: 0.69791667 | AI9: 0.71180556 | AJ9: 0.73125 | AK9: 0.73958333 | AL9: 0.75347222 | AM9: 0.77291667 | AN9: 0.81458333 | AO9: 0.86111111
A10: 6 | B10: Jana Palacha | D10: =D9+"0:03" -> 0.19166667 | E10: =E9+"0:03" -> 0.21388889 | F10: =F9+"0:03" -> 0.23333333 | G10: =G9+"0:03" -> 0.24166667 | H10: =H9+"0:03" -> 0.25555556 | I10: =I9+"0:03" -> 0.275 | J10: =J9+"0:03" -> 0.28333333 | K10: =K9+"0:03" -> 0.29722222 | ... AO10: =AO9+"0:03" -> 0.86319444
A11: 7 | B11: nám.TGM kostel | D11: =D10+"0:03" -> 0.19375 | E11: =E10+"0:03" -> 0.21597222 | F11: =F10+"0:03" -> 0.23541667 | G11: =G10+"0:03" -> 0.24375 | H11: =H10+"0:03" -> 0.25763889 | I11: =I10+"0:03" -> 0.27708333 | J11: =J10+"0:03" -> 0.28541667 | K11: =K10+"0:03" -> 0.29930556 | ... AO11: =AO10+"0:03" -> 0.86527778
A12: 8 | B12: Poštorná,Lesní | D12: =D11+"0:02" -> 0.19513889 | E12: =E11+"0:02" -> 0.21736111 | F12: =F11+"0:02" -> 0.23680556 | G12: =G11+"0:02" -> 0.24513889 | H12: =H11+"0:02" -> 0.25902778 | I12: =I11+"0:02" -> 0.27847222 | J12: =J11+"0:02" -> 0.28680556 | K12: =K11+"0:02" -> 0.30069444 | ... AO12: =AO11+"0:02" -> 0.86666667
A13: 9 | B13: Poštorná,kostel | D13: =D12+"0:01" -> 0.19583333 | E13: =E12+"0:01" -> 0.21805556 | F13: =F12+"0:01" -> 0.2375 | G13: =G12+"0:01" -> 0.24583333 | H13: =H12+"0:01" -> 0.25972222 | I13: =I12+"0:01" -> 0.27916667 | J13: =J12+"0:01" -> 0.2875 | K13: =K12+"0:01" -> 0.30138889 | ... AO13: =AO12+"0:01" -> 0.86736111
A14: 10 | B14: Poštorná,Hlavní | D14: =D13+"0:01" -> 0.19652778 | E14: =E13+"0:01" -> 0.21875 | F14: =F13+"0:01" -> 0.23819444 | G14: =G13+"0:01" -> 0.24652778 | H14: =H13+"0:01" -> 0.26041667 | I14: =I13+"0:01" -> 0.27986111 | J14: =J13+"0:01" -> 0.28819444 | K14: =K13+"0:01" -> 0.30208333 | ... AO14: =AO13+"0:01" -> 0.86805556
A15: 11 | B15: Poštorná,Valtická | D15: =D14+"0:02" -> 0.19791667 | E15: =E14+"0:02" -> 0.22013889 | F15: =F14+"0:02" -> 0.23958333 | G15: =G14+"0:02" -> 0.24791667 | H15: =H14+"0:02" -> 0.26180556 | I15: =I14+"0:02" -> 0.28125 | J15: =J14+"0:02" -> 0.28958333 | K15: =K14+"0:02" -> 0.30347222 | ... AO15: =AO14+"0:02" -> 0.86944444
A16: 12 | B16: Poštorná,Nádražní | D16: ~ | E16: ~ | F16: ~ | G16: ~ | H16: ~ | I16: ~ | J16: ~ | K16: ~ | L16: ~ | M16: ~ | N16: ~ | O16: ~ | P16: ~ | Q16: ~ | R16: ~ | S16: ~ | T16: ~ | U16: ~ | V16: ~ | W16: ~ | X16: ~ | Y16: ~ | Z16: ~ | AA16: ~ | AB16: ~ | AC16: ~ | AD16: ~ | AE16: ~ | AF16: ~ | AG16: ~ | AH16: ~ | AI16: ~ | AJ16: ~ | AK16: ~ | AL16: ~ | AM16: ~ | AN16: ~ | AO16: ~
A17: 13 | B17: Poštorná,PKZ | D17: ~ | E17: ~ | F17: ~ | G17: ~ | H17: ~ | I17: ~ | J17: ~ | K17: ~ | L17: ~ | M17: ~ | N17: ~ | O17: ~ | P17: ~ | Q17: ~ | R17: ~ | S17: ~ | T17: ~ | U17: ~ | V17: ~ | W17: ~ | X17: ~ | Y17: ~ | Z17: ~ | AA17: ~ | AB17: ~ | AC17: ~ | AD17: ~ | AE17: ~ | AF17: ~ | AG17: ~ | AH17: ~ | AI17: ~ | AJ17: ~ | AK17: ~ | AL17: ~ | AM17: ~ | AN17: ~ | AO17: ~
A18: 14 | B18: Poštorná,Tovární čtvrť | D18: ~ | E18: ~ | F18: ~ | G18: ~ | H18: ~ | I18: ~ | J18: ~ | K18: ~ | L18: ~ | M18: ~ | N18: ~ | O18: ~ | P18: ~ | Q18: ~ | R18: ~ | S18: ~ | T18: ~ | U18: ~ | V18: ~ | W18: ~ | X18: ~ | Y18: ~ | Z18: ~ | AA18: ~ | AB18: ~ | AC18: ~ | AD18: ~ | AE18: ~ | AF18: ~ | AG18: ~ | AH18: ~ | AI18: ~ | AJ18: ~ | AK18: ~ | AL18: ~ | AM18: ~ | AN18: ~ | AO18: ~
A19: 15 | B19: Poštorná,Valtická točna | C19: příj. | D19: =D15+"0:02" -> 0.19930556 | E19: =E15+"0:02" -> 0.22152778 | F19: =F15+"0:02" -> 0.24097222 | G19: =G15+"0:02" -> 0.24930556 | H19: =H15+"0:02" -> 0.26319444 | I19: =I15+"0:02" -> 0.28263889 | J19: =J15+"0:02" -> 0.29097222 | K19: =K15+"0:02" -> 0.30486111 | ... AO19: =AO15+"0:02" -> 0.87083333
B20: km | D20: 7 | E20: 4.9 | F20: 7 | G20: 4.9 | H20: 4.9 | I20: 7 | J20: 4.9 | K20: 4.9 | L20: 4.9 | M20: 7 | N20: 4.9 | O20: 4.9 | P20: 4.9 | Q20: 4.9 | R20: 4.9 | S20: 4.9 | T20: 4.9 | U20: 4.9 | V20: 4.9 | W20: 4.9 | X20: 4.9 | Y20: 4.9 | Z20: 4.9 | AA20: 7 | AB20: 4.9 | AC20: 4.9 | AD20: 7 | AE20: 4.9 | AF20: 4.9 | AG20: 7 | AH20: 4.9 | AI20: 4.9 | AJ20: 7 | AK20: 4.9 | AL20: 4.9 | AM20: 4.9 | AN20: 4.9 | AO20: 4.9 | AP20: =SUM(D20:Y20) -> 116.2
A24: Linka číslo 745567 | D24: Valtická Točna - Hlavní - Autobusové Nádraží
B26: návrh k projednání | C26: opačný směr | D26: opačný směr
